[2025-04-05T02:48:14.229+0000] {taskinstance.py:1125} INFO - Dependencies all met for dep_context=non-requeueable deps ti=<TaskInstance: svm_training_dag.train_model scheduled__2025-04-03T00:00:00+00:00 [queued]>
[2025-04-05T02:48:14.305+0000] {taskinstance.py:1125} INFO - Dependencies all met for dep_context=requeueable deps ti=<TaskInstance: svm_training_dag.train_model scheduled__2025-04-03T00:00:00+00:00 [queued]>
[2025-04-05T02:48:14.322+0000] {taskinstance.py:1331} INFO - Starting attempt 1 of 2
[2025-04-05T02:48:14.448+0000] {taskinstance.py:1350} INFO - Executing <Task(PythonOperator): train_model> on 2025-04-03 00:00:00+00:00
[2025-04-05T02:48:14.747+0000] {standard_task_runner.py:57} INFO - Started process 440 to run task
[2025-04-05T02:48:14.759+0000] {standard_task_runner.py:84} INFO - Running: ['***', 'tasks', 'run', 'svm_training_dag', 'train_model', 'scheduled__2025-04-03T00:00:00+00:00', '--job-id', '13', '--raw', '--subdir', 'DAGS_FOLDER/model_train.py', '--cfg-path', '/tmp/tmpz55cj91d']
[2025-04-05T02:48:15.405+0000] {standard_task_runner.py:85} INFO - Job 13: Subtask train_model
[2025-04-05T02:48:16.026+0000] {task_command.py:410} INFO - Running <TaskInstance: svm_training_dag.train_model scheduled__2025-04-03T00:00:00+00:00 [running]> on host 8fa70ebba0d3
[2025-04-05T02:48:16.756+0000] {taskinstance.py:1568} INFO - Exporting env vars: AIRFLOW_CTX_DAG_OWNER='***' AIRFLOW_CTX_DAG_ID='svm_training_dag' AIRFLOW_CTX_TASK_ID='train_model' AIRFLOW_CTX_EXECUTION_DATE='2025-04-03T00:00:00+00:00' AIRFLOW_CTX_TRY_NUMBER='1' AIRFLOW_CTX_DAG_RUN_ID='scheduled__2025-04-03T00:00:00+00:00'
[2025-04-05T02:48:44.995+0000] {connectionpool.py:812} WARNING - Retrying (Retry(total=4, connect=4, read=5, redirect=5, status=5)) after connection broken by 'NewConnectionError('<urllib3.connection.HTTPConnection object at 0x7f25e6ddfe50>: Failed to establish a new connection: [Errno 111] Connection refused')': /api/2.0/mlflow/experiments/get-by-name?experiment_name=mlflow_tracking
[2025-04-05T02:49:10.499+0000] {connectionpool.py:812} WARNING - Retrying (Retry(total=3, connect=3, read=5, redirect=5, status=5)) after connection broken by 'NewConnectionError('<urllib3.connection.HTTPConnection object at 0x7f25e51e8a30>: Failed to establish a new connection: [Errno 111] Connection refused')': /api/2.0/mlflow/experiments/get-by-name?experiment_name=mlflow_tracking
[2025-04-05T02:49:40.032+0000] {connectionpool.py:812} WARNING - Retrying (Retry(total=2, connect=2, read=5, redirect=5, status=5)) after connection broken by 'NewConnectionError('<urllib3.connection.HTTPConnection object at 0x7f25e51e8c70>: Failed to establish a new connection: [Errno 111] Connection refused')': /api/2.0/mlflow/experiments/get-by-name?experiment_name=mlflow_tracking
[2025-04-05T02:50:17.142+0000] {connectionpool.py:812} WARNING - Retrying (Retry(total=1, connect=1, read=5, redirect=5, status=5)) after connection broken by 'NewConnectionError('<urllib3.connection.HTTPConnection object at 0x7f25e51e8b50>: Failed to establish a new connection: [Errno 111] Connection refused')': /api/2.0/mlflow/experiments/get-by-name?experiment_name=mlflow_tracking
[2025-04-05T02:51:10.581+0000] {connectionpool.py:812} WARNING - Retrying (Retry(total=0, connect=0, read=5, redirect=5, status=5)) after connection broken by 'NewConnectionError('<urllib3.connection.HTTPConnection object at 0x7f25e7371070>: Failed to establish a new connection: [Errno 111] Connection refused')': /api/2.0/mlflow/experiments/get-by-name?experiment_name=mlflow_tracking
[2025-04-05T02:51:31.736+0000] {taskinstance.py:1847} ERROR - Task failed with exception
Traceback (most recent call last):
  File "/home/airflow/.local/lib/python3.9/site-packages/urllib3/connection.py", line 174, in _new_conn
    conn = connection.create_connection(
  File "/home/airflow/.local/lib/python3.9/site-packages/urllib3/util/connection.py", line 95, in create_connection
    raise err
  File "/home/airflow/.local/lib/python3.9/site-packages/urllib3/util/connection.py", line 85, in create_connection
    sock.connect(sa)
ConnectionRefusedError: [Errno 111] Connection refused

During handling of the above exception, another exception occurred:

Traceback (most recent call last):
  File "/home/airflow/.local/lib/python3.9/site-packages/urllib3/connectionpool.py", line 703, in urlopen
    httplib_response = self._make_request(
  File "/home/airflow/.local/lib/python3.9/site-packages/urllib3/connectionpool.py", line 398, in _make_request
    conn.request(method, url, **httplib_request_kw)
  File "/home/airflow/.local/lib/python3.9/site-packages/urllib3/connection.py", line 244, in request
    super(HTTPConnection, self).request(method, url, body=body, headers=headers)
  File "/usr/local/lib/python3.9/http/client.py", line 1285, in request
    self._send_request(method, url, body, headers, encode_chunked)
  File "/usr/local/lib/python3.9/http/client.py", line 1331, in _send_request
    self.endheaders(body, encode_chunked=encode_chunked)
  File "/usr/local/lib/python3.9/http/client.py", line 1280, in endheaders
    self._send_output(message_body, encode_chunked=encode_chunked)
  File "/usr/local/lib/python3.9/http/client.py", line 1040, in _send_output
    self.send(msg)
  File "/usr/local/lib/python3.9/http/client.py", line 980, in send
    self.connect()
  File "/home/airflow/.local/lib/python3.9/site-packages/urllib3/connection.py", line 205, in connect
    conn = self._new_conn()
  File "/home/airflow/.local/lib/python3.9/site-packages/urllib3/connection.py", line 186, in _new_conn
    raise NewConnectionError(
urllib3.exceptions.NewConnectionError: <urllib3.connection.HTTPConnection object at 0x7f25e6d72b80>: Failed to establish a new connection: [Errno 111] Connection refused

During handling of the above exception, another exception occurred:

Traceback (most recent call last):
  File "/home/airflow/.local/lib/python3.9/site-packages/requests/adapters.py", line 489, in send
    resp = conn.urlopen(
  File "/home/airflow/.local/lib/python3.9/site-packages/urllib3/connectionpool.py", line 815, in urlopen
    return self.urlopen(
  File "/home/airflow/.local/lib/python3.9/site-packages/urllib3/connectionpool.py", line 815, in urlopen
    return self.urlopen(
  File "/home/airflow/.local/lib/python3.9/site-packages/urllib3/connectionpool.py", line 815, in urlopen
    return self.urlopen(
  [Previous line repeated 2 more times]
  File "/home/airflow/.local/lib/python3.9/site-packages/urllib3/connectionpool.py", line 787, in urlopen
    retries = retries.increment(
  File "/home/airflow/.local/lib/python3.9/site-packages/urllib3/util/retry.py", line 592, in increment
    raise MaxRetryError(_pool, url, error or ResponseError(cause))
urllib3.exceptions.MaxRetryError: HTTPConnectionPool(host='10.43.101.108', port=8081): Max retries exceeded with url: /api/2.0/mlflow/experiments/get-by-name?experiment_name=mlflow_tracking (Caused by NewConnectionError('<urllib3.connection.HTTPConnection object at 0x7f25e6d72b80>: Failed to establish a new connection: [Errno 111] Connection refused'))

During handling of the above exception, another exception occurred:

Traceback (most recent call last):
  File "/home/airflow/.local/lib/python3.9/site-packages/mlflow/utils/rest_utils.py", line 174, in http_request
    return _get_http_response_with_retries(
  File "/home/airflow/.local/lib/python3.9/site-packages/mlflow/utils/rest_utils.py", line 105, in _get_http_response_with_retries
    return session.request(method, url, **kwargs)
  File "/home/airflow/.local/lib/python3.9/site-packages/requests/sessions.py", line 587, in request
    resp = self.send(prep, **send_kwargs)
  File "/home/airflow/.local/lib/python3.9/site-packages/requests/sessions.py", line 701, in send
    r = adapter.send(request, **kwargs)
  File "/home/airflow/.local/lib/python3.9/site-packages/requests/adapters.py", line 565, in send
    raise ConnectionError(e, request=request)
requests.exceptions.ConnectionError: HTTPConnectionPool(host='10.43.101.108', port=8081): Max retries exceeded with url: /api/2.0/mlflow/experiments/get-by-name?experiment_name=mlflow_tracking (Caused by NewConnectionError('<urllib3.connection.HTTPConnection object at 0x7f25e6d72b80>: Failed to establish a new connection: [Errno 111] Connection refused'))

During handling of the above exception, another exception occurred:

Traceback (most recent call last):
  File "/home/airflow/.local/lib/python3.9/site-packages/airflow/operators/python.py", line 181, in execute
    return_value = self.execute_callable()
  File "/home/airflow/.local/lib/python3.9/site-packages/airflow/operators/python.py", line 198, in execute_callable
    return self.python_callable(*self.op_args, **self.op_kwargs)
  File "/opt/airflow/dags/model_train.py", line 97, in model_train
    mlflow.set_experiment("mlflow_tracking")
  File "/home/airflow/.local/lib/python3.9/site-packages/mlflow/tracking/fluent.py", line 113, in set_experiment
    experiment = client.get_experiment_by_name(experiment_name)
  File "/home/airflow/.local/lib/python3.9/site-packages/mlflow/tracking/client.py", line 461, in get_experiment_by_name
    return self._tracking_client.get_experiment_by_name(name)
  File "/home/airflow/.local/lib/python3.9/site-packages/mlflow/tracking/_tracking_service/client.py", line 220, in get_experiment_by_name
    return self.store.get_experiment_by_name(name)
  File "/home/airflow/.local/lib/python3.9/site-packages/mlflow/store/tracking/rest_store.py", line 304, in get_experiment_by_name
    response_proto = self._call_endpoint(GetExperimentByName, req_body)
  File "/home/airflow/.local/lib/python3.9/site-packages/mlflow/store/tracking/rest_store.py", line 56, in _call_endpoint
    return call_endpoint(self.get_host_creds(), endpoint, method, json_body, response_proto)
  File "/home/airflow/.local/lib/python3.9/site-packages/mlflow/utils/rest_utils.py", line 283, in call_endpoint
    response = http_request(
  File "/home/airflow/.local/lib/python3.9/site-packages/mlflow/utils/rest_utils.py", line 192, in http_request
    raise MlflowException(f"API request to {url} failed with exception {e}")
mlflow.exceptions.MlflowException: API request to http://10.43.101.108:8081/api/2.0/mlflow/experiments/get-by-name failed with exception HTTPConnectionPool(host='10.43.101.108', port=8081): Max retries exceeded with url: /api/2.0/mlflow/experiments/get-by-name?experiment_name=mlflow_tracking (Caused by NewConnectionError('<urllib3.connection.HTTPConnection object at 0x7f25e6d72b80>: Failed to establish a new connection: [Errno 111] Connection refused'))
[2025-04-05T02:51:31.968+0000] {taskinstance.py:1368} INFO - Marking task as UP_FOR_RETRY. dag_id=svm_training_dag, task_id=train_model, execution_date=20250403T000000, start_date=20250405T024814, end_date=20250405T025131
[2025-04-05T02:51:32.010+0000] {standard_task_runner.py:104} ERROR - Failed to execute job 13 for task train_model (API request to http://10.43.101.108:8081/api/2.0/mlflow/experiments/get-by-name failed with exception HTTPConnectionPool(host='10.43.101.108', port=8081): Max retries exceeded with url: /api/2.0/mlflow/experiments/get-by-name?experiment_name=mlflow_tracking (Caused by NewConnectionError('<urllib3.connection.HTTPConnection object at 0x7f25e6d72b80>: Failed to establish a new connection: [Errno 111] Connection refused')); 440)
[2025-04-05T02:51:32.063+0000] {local_task_job_runner.py:232} INFO - Task exited with return code 1
[2025-04-05T02:51:32.109+0000] {taskinstance.py:2674} INFO - 0 downstream tasks scheduled from follow-on schedule check
